2022-06-14 10:07:59,762 - middleware.py[line:51] - INFO: Enabled downloader middlewares:
['Qinghai.middlewares.RandomUserAgentMiddleware',
 'scrapy.downloadermiddlewares.httpauth.HttpAuthMiddleware',
 'scrapy.downloadermiddlewares.downloadtimeout.DownloadTimeoutMiddleware',
 'scrapy.downloadermiddlewares.defaultheaders.DefaultHeadersMiddleware',
 'scrapy.downloadermiddlewares.useragent.UserAgentMiddleware',
 'scrapy.downloadermiddlewares.retry.RetryMiddleware',
 'scrapy.downloadermiddlewares.redirect.MetaRefreshMiddleware',
 'scrapy.downloadermiddlewares.httpcompression.HttpCompressionMiddleware',
 'scrapy.downloadermiddlewares.redirect.RedirectMiddleware',
 'scrapy.downloadermiddlewares.cookies.CookiesMiddleware',
 'scrapy.downloadermiddlewares.httpproxy.HttpProxyMiddleware',
 'scrapy.downloadermiddlewares.stats.DownloaderStats']
2022-06-14 10:07:59,764 - middleware.py[line:51] - INFO: Enabled spider middlewares:
['scrapy.spidermiddlewares.httperror.HttpErrorMiddleware',
 'scrapy.spidermiddlewares.offsite.OffsiteMiddleware',
 'scrapy.spidermiddlewares.referer.RefererMiddleware',
 'scrapy.spidermiddlewares.urllength.UrlLengthMiddleware',
 'scrapy.spidermiddlewares.depth.DepthMiddleware']
2022-06-14 10:07:59,766 - middleware.py[line:51] - INFO: Enabled item pipelines:
['Qinghai.pipelines.QinghaiPipeline']
2022-06-14 10:07:59,767 - engine.py[line:313] - INFO: Spider opened
2022-06-14 10:07:59,982 - logstats.py[line:48] - INFO: Crawled 0 pages (at 0 pages/min), scraped 0 items (at 0 items/min)
2022-06-14 10:07:59,983 - telnet.py[line:67] - INFO: Telnet console listening on 127.0.0.1:6023
2022-06-14 10:08:00,654 - engine.py[line:291] - DEBUG: Crawled (200) <GET http://www.59med.com/news/list.php?catid=26&page=2> (referer: None)
2022-06-14 10:08:00,669 - engine.py[line:291] - DEBUG: Crawled (200) <GET http://www.59med.com/news/list.php?catid=26&page=1> (referer: None)
2022-06-14 10:08:01,056 - engine.py[line:291] - DEBUG: Crawled (200) <GET http://www.59med.com/news/list.php?catid=26&page=3> (referer: None)
2022-06-14 10:08:01,504 - engine.py[line:291] - DEBUG: Crawled (200) <GET http://www.59med.com/news/list.php?catid=26&page=4> (referer: None)
2022-06-14 10:08:01,795 - engine.py[line:291] - DEBUG: Crawled (200) <GET http://www.59med.com/news/list.php?catid=26&page=5> (referer: None)
2022-06-14 10:08:02,145 - engine.py[line:291] - DEBUG: Crawled (200) <GET http://www.59med.com/news/list.php?catid=26&page=6> (referer: None)
2022-06-14 10:08:02,585 - engine.py[line:291] - DEBUG: Crawled (200) <GET http://www.59med.com/news/list.php?catid=26&page=7> (referer: None)
2022-06-14 10:08:03,663 - engine.py[line:291] - DEBUG: Crawled (200) <GET http://www.59med.com/news/show.php?itemid=133650> (referer: http://www.59med.com/news/list.php?catid=26&page=2)
2022-06-14 10:08:03,758 - engine.py[line:291] - DEBUG: Crawled (200) <GET http://www.59med.com/news/show.php?itemid=133651> (referer: http://www.59med.com/news/list.php?catid=26&page=2)
2022-06-14 10:08:03,769 - scraper.py[line:275] - DEBUG: Scraped from <200 http://www.59med.com/news/show.php?itemid=133650>
None
2022-06-14 10:08:03,795 - _legacy.py[line:147] - CRITICAL: Unhandled error in Deferred:
2022-06-14 10:08:03,798 - _legacy.py[line:147] - CRITICAL: 
Traceback (most recent call last):
  File "d:\project\venv\lib\site-packages\twisted\python\threadpool.py", line 244, in inContext
    result = inContext.theWork()  # type: ignore[attr-defined]
  File "d:\project\venv\lib\site-packages\twisted\python\threadpool.py", line 260, in <lambda>
    inContext.theWork = lambda: context.call(  # type: ignore[attr-defined]
  File "d:\project\venv\lib\site-packages\twisted\python\context.py", line 117, in callWithContext
    return self.currentContext().callWithContext(ctx, func, *args, **kw)
  File "d:\project\venv\lib\site-packages\twisted\python\context.py", line 82, in callWithContext
    return func(*args, **kw)
  File "d:\project\venv\lib\site-packages\twisted\enterprise\adbapi.py", line 443, in _runInteraction
    result = interaction(trans, *args, **kw)
  File "D:\Te\Teng\Qinghai\Qinghai\pipelines.py", line 55, in insert
    cursor.execute(self.query_sql.format(item['uid']))
  File "d:\project\venv\lib\site-packages\pymysql\cursors.py", line 148, in execute
    result = self._query(query)
  File "d:\project\venv\lib\site-packages\pymysql\cursors.py", line 310, in _query
    conn.query(q)
  File "d:\project\venv\lib\site-packages\pymysql\connections.py", line 548, in query
    self._affected_rows = self._read_query_result(unbuffered=unbuffered)
  File "d:\project\venv\lib\site-packages\pymysql\connections.py", line 775, in _read_query_result
    result.read()
  File "d:\project\venv\lib\site-packages\pymysql\connections.py", line 1156, in read
    first_packet = self.connection._read_packet()
  File "d:\project\venv\lib\site-packages\pymysql\connections.py", line 725, in _read_packet
    packet.raise_for_error()
  File "d:\project\venv\lib\site-packages\pymysql\protocol.py", line 221, in raise_for_error
    err.raise_mysql_exception(self._data)
  File "d:\project\venv\lib\site-packages\pymysql\err.py", line 143, in raise_mysql_exception
    raise errorclass(errno, errval)
pymysql.err.ProgrammingError: (1146, "Table 'crawler2022.zhaobiaoquchong' doesn't exist")
2022-06-14 10:08:03,863 - scraper.py[line:275] - DEBUG: Scraped from <200 http://www.59med.com/news/show.php?itemid=133651>
None
2022-06-14 10:08:03,891 - _legacy.py[line:147] - CRITICAL: Unhandled error in Deferred:
2022-06-14 10:08:03,892 - _legacy.py[line:147] - CRITICAL: 
Traceback (most recent call last):
  File "d:\project\venv\lib\site-packages\twisted\python\threadpool.py", line 244, in inContext
    result = inContext.theWork()  # type: ignore[attr-defined]
  File "d:\project\venv\lib\site-packages\twisted\python\threadpool.py", line 260, in <lambda>
    inContext.theWork = lambda: context.call(  # type: ignore[attr-defined]
  File "d:\project\venv\lib\site-packages\twisted\python\context.py", line 117, in callWithContext
    return self.currentContext().callWithContext(ctx, func, *args, **kw)
  File "d:\project\venv\lib\site-packages\twisted\python\context.py", line 82, in callWithContext
    return func(*args, **kw)
  File "d:\project\venv\lib\site-packages\twisted\enterprise\adbapi.py", line 443, in _runInteraction
    result = interaction(trans, *args, **kw)
  File "D:\Te\Teng\Qinghai\Qinghai\pipelines.py", line 55, in insert
    cursor.execute(self.query_sql.format(item['uid']))
  File "d:\project\venv\lib\site-packages\pymysql\cursors.py", line 148, in execute
    result = self._query(query)
  File "d:\project\venv\lib\site-packages\pymysql\cursors.py", line 310, in _query
    conn.query(q)
  File "d:\project\venv\lib\site-packages\pymysql\connections.py", line 548, in query
    self._affected_rows = self._read_query_result(unbuffered=unbuffered)
  File "d:\project\venv\lib\site-packages\pymysql\connections.py", line 775, in _read_query_result
    result.read()
  File "d:\project\venv\lib\site-packages\pymysql\connections.py", line 1156, in read
    first_packet = self.connection._read_packet()
  File "d:\project\venv\lib\site-packages\pymysql\connections.py", line 725, in _read_packet
    packet.raise_for_error()
  File "d:\project\venv\lib\site-packages\pymysql\protocol.py", line 221, in raise_for_error
    err.raise_mysql_exception(self._data)
  File "d:\project\venv\lib\site-packages\pymysql\err.py", line 143, in raise_mysql_exception
    raise errorclass(errno, errval)
pymysql.err.ProgrammingError: (1146, "Table 'crawler2022.zhaobiaoquchong' doesn't exist")
2022-06-14 10:08:04,286 - engine.py[line:291] - DEBUG: Crawled (200) <GET http://www.59med.com/news/show.php?itemid=133652> (referer: http://www.59med.com/news/list.php?catid=26&page=2)
2022-06-14 10:08:04,400 - scraper.py[line:275] - DEBUG: Scraped from <200 http://www.59med.com/news/show.php?itemid=133652>
None
2022-06-14 10:08:04,409 - engine.py[line:291] - DEBUG: Crawled (200) <GET http://www.59med.com/news/show.php?itemid=133653> (referer: http://www.59med.com/news/list.php?catid=26&page=2)
2022-06-14 10:08:04,440 - _legacy.py[line:147] - CRITICAL: Unhandled error in Deferred:
2022-06-14 10:08:04,441 - _legacy.py[line:147] - CRITICAL: 
Traceback (most recent call last):
  File "d:\project\venv\lib\site-packages\twisted\python\threadpool.py", line 244, in inContext
    result = inContext.theWork()  # type: ignore[attr-defined]
  File "d:\project\venv\lib\site-packages\twisted\python\threadpool.py", line 260, in <lambda>
    inContext.theWork = lambda: context.call(  # type: ignore[attr-defined]
  File "d:\project\venv\lib\site-packages\twisted\python\context.py", line 117, in callWithContext
    return self.currentContext().callWithContext(ctx, func, *args, **kw)
  File "d:\project\venv\lib\site-packages\twisted\python\context.py", line 82, in callWithContext
    return func(*args, **kw)
  File "d:\project\venv\lib\site-packages\twisted\enterprise\adbapi.py", line 443, in _runInteraction
    result = interaction(trans, *args, **kw)
  File "D:\Te\Teng\Qinghai\Qinghai\pipelines.py", line 55, in insert
    cursor.execute(self.query_sql.format(item['uid']))
  File "d:\project\venv\lib\site-packages\pymysql\cursors.py", line 148, in execute
    result = self._query(query)
  File "d:\project\venv\lib\site-packages\pymysql\cursors.py", line 310, in _query
    conn.query(q)
  File "d:\project\venv\lib\site-packages\pymysql\connections.py", line 548, in query
    self._affected_rows = self._read_query_result(unbuffered=unbuffered)
  File "d:\project\venv\lib\site-packages\pymysql\connections.py", line 775, in _read_query_result
    result.read()
  File "d:\project\venv\lib\site-packages\pymysql\connections.py", line 1156, in read
    first_packet = self.connection._read_packet()
  File "d:\project\venv\lib\site-packages\pymysql\connections.py", line 725, in _read_packet
    packet.raise_for_error()
  File "d:\project\venv\lib\site-packages\pymysql\protocol.py", line 221, in raise_for_error
    err.raise_mysql_exception(self._data)
  File "d:\project\venv\lib\site-packages\pymysql\err.py", line 143, in raise_mysql_exception
    raise errorclass(errno, errval)
pymysql.err.ProgrammingError: (1146, "Table 'crawler2022.zhaobiaoquchong' doesn't exist")
2022-06-14 10:08:04,522 - scraper.py[line:275] - DEBUG: Scraped from <200 http://www.59med.com/news/show.php?itemid=133653>
None
2022-06-14 10:08:04,530 - _legacy.py[line:147] - CRITICAL: Unhandled error in Deferred:
2022-06-14 10:08:04,530 - _legacy.py[line:147] - CRITICAL: 
Traceback (most recent call last):
  File "d:\project\venv\lib\site-packages\twisted\python\threadpool.py", line 244, in inContext
    result = inContext.theWork()  # type: ignore[attr-defined]
  File "d:\project\venv\lib\site-packages\twisted\python\threadpool.py", line 260, in <lambda>
    inContext.theWork = lambda: context.call(  # type: ignore[attr-defined]
  File "d:\project\venv\lib\site-packages\twisted\python\context.py", line 117, in callWithContext
    return self.currentContext().callWithContext(ctx, func, *args, **kw)
  File "d:\project\venv\lib\site-packages\twisted\python\context.py", line 82, in callWithContext
    return func(*args, **kw)
  File "d:\project\venv\lib\site-packages\twisted\enterprise\adbapi.py", line 443, in _runInteraction
    result = interaction(trans, *args, **kw)
  File "D:\Te\Teng\Qinghai\Qinghai\pipelines.py", line 55, in insert
    cursor.execute(self.query_sql.format(item['uid']))
  File "d:\project\venv\lib\site-packages\pymysql\cursors.py", line 148, in execute
    result = self._query(query)
  File "d:\project\venv\lib\site-packages\pymysql\cursors.py", line 310, in _query
    conn.query(q)
  File "d:\project\venv\lib\site-packages\pymysql\connections.py", line 548, in query
    self._affected_rows = self._read_query_result(unbuffered=unbuffered)
  File "d:\project\venv\lib\site-packages\pymysql\connections.py", line 775, in _read_query_result
    result.read()
  File "d:\project\venv\lib\site-packages\pymysql\connections.py", line 1156, in read
    first_packet = self.connection._read_packet()
  File "d:\project\venv\lib\site-packages\pymysql\connections.py", line 725, in _read_packet
    packet.raise_for_error()
  File "d:\project\venv\lib\site-packages\pymysql\protocol.py", line 221, in raise_for_error
    err.raise_mysql_exception(self._data)
  File "d:\project\venv\lib\site-packages\pymysql\err.py", line 143, in raise_mysql_exception
    raise errorclass(errno, errval)
pymysql.err.ProgrammingError: (1146, "Table 'crawler2022.zhaobiaoquchong' doesn't exist")
2022-06-14 10:08:04,777 - engine.py[line:291] - DEBUG: Crawled (200) <GET http://www.59med.com/news/show.php?itemid=133654> (referer: http://www.59med.com/news/list.php?catid=26&page=2)
2022-06-14 10:08:04,893 - scraper.py[line:275] - DEBUG: Scraped from <200 http://www.59med.com/news/show.php?itemid=133654>
None
2022-06-14 10:08:04,900 - _legacy.py[line:147] - CRITICAL: Unhandled error in Deferred:
2022-06-14 10:08:04,900 - _legacy.py[line:147] - CRITICAL: 
Traceback (most recent call last):
  File "d:\project\venv\lib\site-packages\twisted\python\threadpool.py", line 244, in inContext
    result = inContext.theWork()  # type: ignore[attr-defined]
  File "d:\project\venv\lib\site-packages\twisted\python\threadpool.py", line 260, in <lambda>
    inContext.theWork = lambda: context.call(  # type: ignore[attr-defined]
  File "d:\project\venv\lib\site-packages\twisted\python\context.py", line 117, in callWithContext
    return self.currentContext().callWithContext(ctx, func, *args, **kw)
  File "d:\project\venv\lib\site-packages\twisted\python\context.py", line 82, in callWithContext
    return func(*args, **kw)
  File "d:\project\venv\lib\site-packages\twisted\enterprise\adbapi.py", line 443, in _runInteraction
    result = interaction(trans, *args, **kw)
  File "D:\Te\Teng\Qinghai\Qinghai\pipelines.py", line 55, in insert
    cursor.execute(self.query_sql.format(item['uid']))
  File "d:\project\venv\lib\site-packages\pymysql\cursors.py", line 148, in execute
    result = self._query(query)
  File "d:\project\venv\lib\site-packages\pymysql\cursors.py", line 310, in _query
    conn.query(q)
  File "d:\project\venv\lib\site-packages\pymysql\connections.py", line 548, in query
    self._affected_rows = self._read_query_result(unbuffered=unbuffered)
  File "d:\project\venv\lib\site-packages\pymysql\connections.py", line 775, in _read_query_result
    result.read()
  File "d:\project\venv\lib\site-packages\pymysql\connections.py", line 1156, in read
    first_packet = self.connection._read_packet()
  File "d:\project\venv\lib\site-packages\pymysql\connections.py", line 725, in _read_packet
    packet.raise_for_error()
  File "d:\project\venv\lib\site-packages\pymysql\protocol.py", line 221, in raise_for_error
    err.raise_mysql_exception(self._data)
  File "d:\project\venv\lib\site-packages\pymysql\err.py", line 143, in raise_mysql_exception
    raise errorclass(errno, errval)
pymysql.err.ProgrammingError: (1146, "Table 'crawler2022.zhaobiaoquchong' doesn't exist")
2022-06-14 10:08:05,447 - engine.py[line:291] - DEBUG: Crawled (200) <GET http://www.59med.com/news/show.php?itemid=133655> (referer: http://www.59med.com/news/list.php?catid=26&page=2)
2022-06-14 10:08:05,561 - scraper.py[line:275] - DEBUG: Scraped from <200 http://www.59med.com/news/show.php?itemid=133655>
None
2022-06-14 10:08:05,568 - _legacy.py[line:147] - CRITICAL: Unhandled error in Deferred:
2022-06-14 10:08:05,568 - _legacy.py[line:147] - CRITICAL: 
Traceback (most recent call last):
  File "d:\project\venv\lib\site-packages\twisted\python\threadpool.py", line 244, in inContext
    result = inContext.theWork()  # type: ignore[attr-defined]
  File "d:\project\venv\lib\site-packages\twisted\python\threadpool.py", line 260, in <lambda>
    inContext.theWork = lambda: context.call(  # type: ignore[attr-defined]
  File "d:\project\venv\lib\site-packages\twisted\python\context.py", line 117, in callWithContext
    return self.currentContext().callWithContext(ctx, func, *args, **kw)
  File "d:\project\venv\lib\site-packages\twisted\python\context.py", line 82, in callWithContext
    return func(*args, **kw)
  File "d:\project\venv\lib\site-packages\twisted\enterprise\adbapi.py", line 443, in _runInteraction
    result = interaction(trans, *args, **kw)
  File "D:\Te\Teng\Qinghai\Qinghai\pipelines.py", line 55, in insert
    cursor.execute(self.query_sql.format(item['uid']))
  File "d:\project\venv\lib\site-packages\pymysql\cursors.py", line 148, in execute
    result = self._query(query)
  File "d:\project\venv\lib\site-packages\pymysql\cursors.py", line 310, in _query
    conn.query(q)
  File "d:\project\venv\lib\site-packages\pymysql\connections.py", line 548, in query
    self._affected_rows = self._read_query_result(unbuffered=unbuffered)
  File "d:\project\venv\lib\site-packages\pymysql\connections.py", line 775, in _read_query_result
    result.read()
  File "d:\project\venv\lib\site-packages\pymysql\connections.py", line 1156, in read
    first_packet = self.connection._read_packet()
  File "d:\project\venv\lib\site-packages\pymysql\connections.py", line 725, in _read_packet
    packet.raise_for_error()
  File "d:\project\venv\lib\site-packages\pymysql\protocol.py", line 221, in raise_for_error
    err.raise_mysql_exception(self._data)
  File "d:\project\venv\lib\site-packages\pymysql\err.py", line 143, in raise_mysql_exception
    raise errorclass(errno, errval)
pymysql.err.ProgrammingError: (1146, "Table 'crawler2022.zhaobiaoquchong' doesn't exist")
2022-06-14 10:08:05,977 - engine.py[line:291] - DEBUG: Crawled (200) <GET http://www.59med.com/news/show.php?itemid=133656> (referer: http://www.59med.com/news/list.php?catid=26&page=2)
2022-06-14 10:08:06,084 - scraper.py[line:275] - DEBUG: Scraped from <200 http://www.59med.com/news/show.php?itemid=133656>
None
2022-06-14 10:08:06,090 - _legacy.py[line:147] - CRITICAL: Unhandled error in Deferred:
2022-06-14 10:08:06,090 - _legacy.py[line:147] - CRITICAL: 
Traceback (most recent call last):
  File "d:\project\venv\lib\site-packages\twisted\python\threadpool.py", line 244, in inContext
    result = inContext.theWork()  # type: ignore[attr-defined]
  File "d:\project\venv\lib\site-packages\twisted\python\threadpool.py", line 260, in <lambda>
    inContext.theWork = lambda: context.call(  # type: ignore[attr-defined]
  File "d:\project\venv\lib\site-packages\twisted\python\context.py", line 117, in callWithContext
    return self.currentContext().callWithContext(ctx, func, *args, **kw)
  File "d:\project\venv\lib\site-packages\twisted\python\context.py", line 82, in callWithContext
    return func(*args, **kw)
  File "d:\project\venv\lib\site-packages\twisted\enterprise\adbapi.py", line 443, in _runInteraction
    result = interaction(trans, *args, **kw)
  File "D:\Te\Teng\Qinghai\Qinghai\pipelines.py", line 55, in insert
    cursor.execute(self.query_sql.format(item['uid']))
  File "d:\project\venv\lib\site-packages\pymysql\cursors.py", line 148, in execute
    result = self._query(query)
  File "d:\project\venv\lib\site-packages\pymysql\cursors.py", line 310, in _query
    conn.query(q)
  File "d:\project\venv\lib\site-packages\pymysql\connections.py", line 548, in query
    self._affected_rows = self._read_query_result(unbuffered=unbuffered)
  File "d:\project\venv\lib\site-packages\pymysql\connections.py", line 775, in _read_query_result
    result.read()
  File "d:\project\venv\lib\site-packages\pymysql\connections.py", line 1156, in read
    first_packet = self.connection._read_packet()
  File "d:\project\venv\lib\site-packages\pymysql\connections.py", line 725, in _read_packet
    packet.raise_for_error()
  File "d:\project\venv\lib\site-packages\pymysql\protocol.py", line 221, in raise_for_error
    err.raise_mysql_exception(self._data)
  File "d:\project\venv\lib\site-packages\pymysql\err.py", line 143, in raise_mysql_exception
    raise errorclass(errno, errval)
pymysql.err.ProgrammingError: (1146, "Table 'crawler2022.zhaobiaoquchong' doesn't exist")
2022-06-14 10:08:06,493 - engine.py[line:291] - DEBUG: Crawled (200) <GET http://www.59med.com/news/show.php?itemid=133657> (referer: http://www.59med.com/news/list.php?catid=26&page=2)
2022-06-14 10:08:06,597 - scraper.py[line:275] - DEBUG: Scraped from <200 http://www.59med.com/news/show.php?itemid=133657>
None
2022-06-14 10:08:06,605 - _legacy.py[line:147] - CRITICAL: Unhandled error in Deferred:
2022-06-14 10:08:06,605 - _legacy.py[line:147] - CRITICAL: 
Traceback (most recent call last):
  File "d:\project\venv\lib\site-packages\twisted\python\threadpool.py", line 244, in inContext
    result = inContext.theWork()  # type: ignore[attr-defined]
  File "d:\project\venv\lib\site-packages\twisted\python\threadpool.py", line 260, in <lambda>
    inContext.theWork = lambda: context.call(  # type: ignore[attr-defined]
  File "d:\project\venv\lib\site-packages\twisted\python\context.py", line 117, in callWithContext
    return self.currentContext().callWithContext(ctx, func, *args, **kw)
  File "d:\project\venv\lib\site-packages\twisted\python\context.py", line 82, in callWithContext
    return func(*args, **kw)
  File "d:\project\venv\lib\site-packages\twisted\enterprise\adbapi.py", line 443, in _runInteraction
    result = interaction(trans, *args, **kw)
  File "D:\Te\Teng\Qinghai\Qinghai\pipelines.py", line 55, in insert
    cursor.execute(self.query_sql.format(item['uid']))
  File "d:\project\venv\lib\site-packages\pymysql\cursors.py", line 148, in execute
    result = self._query(query)
  File "d:\project\venv\lib\site-packages\pymysql\cursors.py", line 310, in _query
    conn.query(q)
  File "d:\project\venv\lib\site-packages\pymysql\connections.py", line 548, in query
    self._affected_rows = self._read_query_result(unbuffered=unbuffered)
  File "d:\project\venv\lib\site-packages\pymysql\connections.py", line 775, in _read_query_result
    result.read()
  File "d:\project\venv\lib\site-packages\pymysql\connections.py", line 1156, in read
    first_packet = self.connection._read_packet()
  File "d:\project\venv\lib\site-packages\pymysql\connections.py", line 725, in _read_packet
    packet.raise_for_error()
  File "d:\project\venv\lib\site-packages\pymysql\protocol.py", line 221, in raise_for_error
    err.raise_mysql_exception(self._data)
  File "d:\project\venv\lib\site-packages\pymysql\err.py", line 143, in raise_mysql_exception
    raise errorclass(errno, errval)
pymysql.err.ProgrammingError: (1146, "Table 'crawler2022.zhaobiaoquchong' doesn't exist")
2022-06-14 10:08:07,051 - engine.py[line:291] - DEBUG: Crawled (200) <GET http://www.59med.com/news/show.php?itemid=133658> (referer: http://www.59med.com/news/list.php?catid=26&page=2)
2022-06-14 10:08:07,166 - scraper.py[line:275] - DEBUG: Scraped from <200 http://www.59med.com/news/show.php?itemid=133658>
None
2022-06-14 10:08:07,176 - _legacy.py[line:147] - CRITICAL: Unhandled error in Deferred:
2022-06-14 10:08:07,177 - _legacy.py[line:147] - CRITICAL: 
Traceback (most recent call last):
  File "d:\project\venv\lib\site-packages\twisted\python\threadpool.py", line 244, in inContext
    result = inContext.theWork()  # type: ignore[attr-defined]
  File "d:\project\venv\lib\site-packages\twisted\python\threadpool.py", line 260, in <lambda>
    inContext.theWork = lambda: context.call(  # type: ignore[attr-defined]
  File "d:\project\venv\lib\site-packages\twisted\python\context.py", line 117, in callWithContext
    return self.currentContext().callWithContext(ctx, func, *args, **kw)
  File "d:\project\venv\lib\site-packages\twisted\python\context.py", line 82, in callWithContext
    return func(*args, **kw)
  File "d:\project\venv\lib\site-packages\twisted\enterprise\adbapi.py", line 443, in _runInteraction
    result = interaction(trans, *args, **kw)
  File "D:\Te\Teng\Qinghai\Qinghai\pipelines.py", line 55, in insert
    cursor.execute(self.query_sql.format(item['uid']))
  File "d:\project\venv\lib\site-packages\pymysql\cursors.py", line 148, in execute
    result = self._query(query)
  File "d:\project\venv\lib\site-packages\pymysql\cursors.py", line 310, in _query
    conn.query(q)
  File "d:\project\venv\lib\site-packages\pymysql\connections.py", line 548, in query
    self._affected_rows = self._read_query_result(unbuffered=unbuffered)
  File "d:\project\venv\lib\site-packages\pymysql\connections.py", line 775, in _read_query_result
    result.read()
  File "d:\project\venv\lib\site-packages\pymysql\connections.py", line 1156, in read
    first_packet = self.connection._read_packet()
  File "d:\project\venv\lib\site-packages\pymysql\connections.py", line 725, in _read_packet
    packet.raise_for_error()
  File "d:\project\venv\lib\site-packages\pymysql\protocol.py", line 221, in raise_for_error
    err.raise_mysql_exception(self._data)
  File "d:\project\venv\lib\site-packages\pymysql\err.py", line 143, in raise_mysql_exception
    raise errorclass(errno, errval)
pymysql.err.ProgrammingError: (1146, "Table 'crawler2022.zhaobiaoquchong' doesn't exist")
2022-06-14 10:08:07,350 - engine.py[line:291] - DEBUG: Crawled (200) <GET http://www.59med.com/news/show.php?itemid=133659> (referer: http://www.59med.com/news/list.php?catid=26&page=1)
2022-06-14 10:08:07,457 - scraper.py[line:275] - DEBUG: Scraped from <200 http://www.59med.com/news/show.php?itemid=133659>
None
2022-06-14 10:08:07,462 - _legacy.py[line:147] - CRITICAL: Unhandled error in Deferred:
2022-06-14 10:08:07,462 - _legacy.py[line:147] - CRITICAL: 
Traceback (most recent call last):
  File "d:\project\venv\lib\site-packages\twisted\python\threadpool.py", line 244, in inContext
    result = inContext.theWork()  # type: ignore[attr-defined]
  File "d:\project\venv\lib\site-packages\twisted\python\threadpool.py", line 260, in <lambda>
    inContext.theWork = lambda: context.call(  # type: ignore[attr-defined]
  File "d:\project\venv\lib\site-packages\twisted\python\context.py", line 117, in callWithContext
    return self.currentContext().callWithContext(ctx, func, *args, **kw)
  File "d:\project\venv\lib\site-packages\twisted\python\context.py", line 82, in callWithContext
    return func(*args, **kw)
  File "d:\project\venv\lib\site-packages\twisted\enterprise\adbapi.py", line 443, in _runInteraction
    result = interaction(trans, *args, **kw)
  File "D:\Te\Teng\Qinghai\Qinghai\pipelines.py", line 55, in insert
    cursor.execute(self.query_sql.format(item['uid']))
  File "d:\project\venv\lib\site-packages\pymysql\cursors.py", line 148, in execute
    result = self._query(query)
  File "d:\project\venv\lib\site-packages\pymysql\cursors.py", line 310, in _query
    conn.query(q)
  File "d:\project\venv\lib\site-packages\pymysql\connections.py", line 548, in query
    self._affected_rows = self._read_query_result(unbuffered=unbuffered)
  File "d:\project\venv\lib\site-packages\pymysql\connections.py", line 775, in _read_query_result
    result.read()
  File "d:\project\venv\lib\site-packages\pymysql\connections.py", line 1156, in read
    first_packet = self.connection._read_packet()
  File "d:\project\venv\lib\site-packages\pymysql\connections.py", line 725, in _read_packet
    packet.raise_for_error()
  File "d:\project\venv\lib\site-packages\pymysql\protocol.py", line 221, in raise_for_error
    err.raise_mysql_exception(self._data)
  File "d:\project\venv\lib\site-packages\pymysql\err.py", line 143, in raise_mysql_exception
    raise errorclass(errno, errval)
pymysql.err.ProgrammingError: (1146, "Table 'crawler2022.zhaobiaoquchong' doesn't exist")
